Traceback (most recent call last):
  File "/Users/advaitdesai/Programming/eklavya/arhan_execute/main.py", line 181, in <module>
    envs = SyncVectorEnv([make_env(i) for i in range(NUM_ENVS)])
  File "/Users/advaitdesai/Programming/eklavya/venv/lib/python3.10/site-packages/gymnasium/vector/sync_vector_env.py", line 97, in __init__
    self.envs = [env_fn() for env_fn in env_fns]
  File "/Users/advaitdesai/Programming/eklavya/venv/lib/python3.10/site-packages/gymnasium/vector/sync_vector_env.py", line 97, in <listcomp>
    self.envs = [env_fn() for env_fn in env_fns]
  File "/Users/advaitdesai/Programming/eklavya/arhan_execute/main.py", line 173, in _init
    return CustomAntEnv(
TypeError: CustomAntEnv.__init__() got an unexpected keyword argument 'max_episode_steps'
